Workbook
Name UPDATE: 'Data Sheet'!$E$1

Sheet HISTORICAL FS
B1: ="HISTORICAL FINANCIAL STATEMENT-"&'Data Sheet'!B1 -> HISTORICAL FINANCIAL STATEMENT-RELIANCE INDUSTRIES LTD
B2: YEAR | C2: ='Data Sheet'!B16 -> 42460 | D2: ='Data Sheet'!C16 -> 42825 | E2: ='Data Sheet'!D16 -> 43190 | F2: ='Data Sheet'!E16 -> 43555 | G2: ='Data Sheet'!F16 -> 43921 | H2: ='Data Sheet'!G16 -> 44286 | I2: ='Data Sheet'!H16 -> 44651 | J2: ='Data Sheet'!I16 -> 45016 | ... L2: ='Data Sheet'!K16 -> 45747 | M2: LTM
B3: INCOME STATEMENT
B4: Salas | C4: =IFERROR('Data Sheet'!B17,0) -> 272583 | D4: =IFERROR('Data Sheet'!C17,0) -> 303954 | E4: =IFERROR('Data Sheet'!D17,0) -> 390823 | F4: =IFERROR('Data Sheet'!E17,0) -> 568337 | G4: =IFERROR('Data Sheet'!F17,0) -> 596679 | H4: =IFERROR('Data Sheet'!G17,0) -> 466307 | I4: =IFERROR('Data Sheet'!H17,0) -> 694673 | J4: =IFERROR('Data Sheet'!I17,0) -> 876396 | ... L4: =IFERROR('Data Sheet'!K17,0) -> 962820 | M4: =IFERROR(SUM('Data Sheet'!H17:K17),0) -> 3432930
B5: salas Growth | C5: - | D5: =D4/C4-1 -> 0.11508788 | E5: =E4/D4-1 -> 0.28579654 | F5: =F4/E4-1 -> 0.45420561 | G5: =G4/F4-1 -> 0.0498683 | H5: =H4/G4-1 -> -0.21849604 | I5: =I4/H4-1 -> 0.48973316 | J5: =J4/I4-1 -> 0.26159502 | K5: =K4/J4-1 -> 0.025838776 | ... M5: =M4/L4-1 -> 2.5654951
B7: COGS | C7: =IFERROR(SUM('Data Sheet'!B18,'Data Sheet'!B20,'Data Sheet'!B21,'Data Sheet'!B22,)-1*'Data Sheet'!B19,0) -> 215234 | D7: =IFERROR(SUM('Data Sheet'!C18,'Data Sheet'!C20,'Data Sheet'!C21,'Data Sheet'!C22,)-1*'Data Sheet'!C19,0) -> 241848 | E7: =IFERROR(SUM('Data Sheet'!D18,'Data Sheet'!D20,'Data Sheet'!D21,'Data Sheet'!D22,)-1*'Data Sheet'!D19,0) -> 301249 | F7: =IFERROR(SUM('Data Sheet'!E18,'Data Sheet'!E20,'Data Sheet'!E21,'Data Sheet'!E22,)-1*'Data Sheet'!E19,0) -> 436202 | G7: =IFERROR(SUM('Data Sheet'!F18,'Data Sheet'!F20,'Data Sheet'!F21,'Data Sheet'!F22,)-1*'Data Sheet'!F19,0) -> 445847 | H7: =IFERROR(SUM('Data Sheet'!G18,'Data Sheet'!G20,'Data Sheet'!G21,'Data Sheet'!G22,)-1*'Data Sheet'!G19,0) -> 328419 | I7: =IFERROR(SUM('Data Sheet'!H18,'Data Sheet'!H20,'Data Sheet'!H21,'Data Sheet'!H22,)-1*'Data Sheet'!H19,0) -> 521826 | J7: =IFERROR(SUM('Data Sheet'!I18,'Data Sheet'!I20,'Data Sheet'!I21,'Data Sheet'!I22,)-1*'Data Sheet'!I19,0) -> 658075 | ... L7: =IFERROR(SUM('Data Sheet'!K18,'Data Sheet'!K20,'Data Sheet'!K21,'Data Sheet'!K22,)-1*'Data Sheet'!K19,0) -> 700429 | M7: =IFERROR(SUM('Data Sheet'!H42:K42),0) -> 999629
B8: COGS % Salas | C8: =C7/C4 -> 0.78960904 | D8: =D7/D4 -> 0.79567303 | E8: =E7/E4 -> 0.77080673 | F8: =F7/F4 -> 0.7675059 | G8: =G7/G4 -> 0.74721416 | H8: =H7/H4 -> 0.70429781 | I8: =I7/I4 -> 0.75118221 | J8: =J7/J4 -> 0.75088773 | ... M8: =M7/M4 -> 0.29118829
B10: GROSS PROFIT | C10: =C4-C7 -> 57349 | D10: =D4-D7 -> 62106 | E10: =E4-E7 -> 89574 | F10: =F4-F7 -> 132135 | G10: =G4-G7 -> 150832 | H10: =H4-H7 -> 137888 | I10: =I4-I7 -> 172847 | J10: =J4-J7 -> 218321 | ... M10: =M4-M7 -> 2433301
B11: Gross Margin | C11: =C10/C4 -> 0.21039096 | D11: =D10/D4 -> 0.20432697 | E11: =E10/E4 -> 0.22919327 | F11: =F10/F4 -> 0.2324941 | G11: =G10/G4 -> 0.25278584 | H11: =H10/H4 -> 0.29570219 | I11: =I10/I4 -> 0.24881779 | J11: =J10/J4 -> 0.24911227 | ... M11: =M10/M4 -> 0.70881171
B13: SELLING & GENEREAL EXP | C13: =IFERROR(SUM('Data Sheet'!B23,'Data Sheet'!B24),0) -> 15568 | D13: =IFERROR(SUM('Data Sheet'!C23,'Data Sheet'!C24),0) -> 15799 | E13: =IFERROR(SUM('Data Sheet'!D23,'Data Sheet'!D24),0) -> 25259 | F13: =IFERROR(SUM('Data Sheet'!E23,'Data Sheet'!E24),0) -> 47885 | G13: =IFERROR(SUM('Data Sheet'!F23,'Data Sheet'!F24),0) -> 61566 | H13: =IFERROR(SUM('Data Sheet'!G23,'Data Sheet'!G24),0) -> 57098 | I13: =IFERROR(SUM('Data Sheet'!H23,'Data Sheet'!H24),0) -> 64266 | J13: =IFERROR(SUM('Data Sheet'!I23,'Data Sheet'!I24),0) -> 76003 | ... M13: =IFERROR(SUM('Data Sheet'!L23,'Data Sheet'!L24),0) -> 0
B14: S&A Exp % Salas | C14: =C13/C4 -> 0.057112879 | D14: =D13/D4 -> 0.05197826 | E14: =E13/E4 -> 0.06463028 | F14: =F13/F4 -> 0.084254588 | G14: =G13/G4 -> 0.10318111 | H14: =H13/H4 -> 0.12244723 | I14: =I13/I4 -> 0.092512592 | J14: =J13/J4 -> 0.086722212 | ... M14: =M13/M4 -> 0
B16: EBIDA | C16: =C10-C13 -> 41781 | D16: =D10-D13 -> 46307 | E16: =E10-E13 -> 64315 | F16: =F10-F13 -> 84250 | G16: =G10-G13 -> 89266 | H16: =H10-H13 -> 80790 | I16: =I10-I13 -> 108581 | J16: =J10-J13 -> 142318 | ... M16: =M10-M13 -> 2433301
B17: EBIDA % Salas | C17: =C16/C4 -> 0.15327808 | D17: =D16/D4 -> 0.15234871 | E17: =E16/E4 -> 0.16456299 | F17: =F16/F4 -> 0.14823951 | G17: =G16/G4 -> 0.14960473 | H17: =H16/H4 -> 0.17325496 | I17: =I16/I4 -> 0.1563052 | J17: =J16/J4 -> 0.16239006 | ... M17: =M16/M4 -> 0.70881171
B19: INTEREST | C19: =IFERROR('Data Sheet'!B27,0) -> 3691 | D19: =IFERROR('Data Sheet'!C27,0) -> 3849 | E19: =IFERROR('Data Sheet'!D27,0) -> 8052 | F19: =IFERROR('Data Sheet'!E27,0) -> 16495 | G19: =IFERROR('Data Sheet'!F27,0) -> 22027 | H19: =IFERROR('Data Sheet'!G27,0) -> 21189 | I19: =IFERROR('Data Sheet'!H27,0) -> 14584 | J19: =IFERROR('Data Sheet'!I27,0) -> 19571 | ... L19: =IFERROR('Data Sheet'!K27,0) -> 24269 | M19: =IFERROR(SUM('Data Sheet'!H27:K27),0) -> 81542
B20: Interest % Salas | C20: =C19/C4 -> 0.01354083 | D20: =D19/D4 -> 0.0126631 | E20: =E19/E4 -> 0.020602677 | F20: =F19/F4 -> 0.029023273 | G20: =G19/G4 -> 0.036915997 | H20: =H19/H4 -> 0.045440021 | I20: =I19/I4 -> 0.02099405 | J20: =J19/J4 -> 0.022331229 | ... M20: =M19/M4 -> 0.023752887
B22: Depreciation | C22: =IFERROR('Data Sheet'!B26,0) -> 11565 | D22: =IFERROR('Data Sheet'!C26,0) -> 11646 | E22: =IFERROR('Data Sheet'!D26,0) -> 16706 | F22: =IFERROR('Data Sheet'!E26,0) -> 20934 | G22: =IFERROR('Data Sheet'!F26,0) -> 22203 | H22: =IFERROR('Data Sheet'!G26,0) -> 26572 | I22: =IFERROR('Data Sheet'!H26,0) -> 29782 | J22: =IFERROR('Data Sheet'!I26,0) -> 40303 | ... L22: =IFERROR('Data Sheet'!K26,0) -> 53136 | M22: =IFERROR(SUM('Data Sheet'!H26:K26),0) -> 174053
B23: Depreciation % Salas | C23: =C22/C4 -> 0.042427444 | D23: =D22/D4 -> 0.038315008 | E23: =E22/E4 -> 0.042745693 | F23: =F22/F4 -> 0.03683378 | G23: =G22/G4 -> 0.037210963 | H23: =H22/H4 -> 0.056983918 | I23: =I22/I4 -> 0.04287197 | J23: =J22/J4 -> 0.045987202 | ... M23: =M22/M4 -> 0.050701005
B25: Earning Before Taxes | C25: =IFERROR(C16-SUM(C19,C22),0) -> 26525 | D25: =IFERROR(D16-SUM(D19,D22),0) -> 30812 | E25: =IFERROR(E16-SUM(E19,E22),0) -> 39557 | F25: =IFERROR(F16-SUM(F19,F22),0) -> 46821 | G25: =IFERROR(G16-SUM(G19,G22),0) -> 45036 | H25: =IFERROR(H16-SUM(H19,H22),0) -> 33029 | I25: =IFERROR(I16-SUM(I19,I22),0) -> 64215 | J25: =IFERROR(J16-SUM(J19,J22),0) -> 82444 | ... M25: =IFERROR(M16-SUM(M19,M22),0) -> 2177706
B26: EBT % Salas | C26: =C25/C4 -> 0.09730981 | D26: =D25/D4 -> 0.1013706 | E26: =E25/E4 -> 0.10121462 | F26: =F25/F4 -> 0.08238246 | G26: =G25/G4 -> 0.075477769 | H26: =H25/H4 -> 0.070831019 | I26: =I25/I4 -> 0.092439176 | J26: =J25/J4 -> 0.09407163 | ... M26: =M25/M4 -> 0.63435782
B28: TAX | C28: =IFERROR('Data Sheet'!B29,0) -> 8876 | D28: =IFERROR('Data Sheet'!C29,0) -> 10201 | E28: =IFERROR('Data Sheet'!D29,0) -> 13346 | F28: =IFERROR('Data Sheet'!E29,0) -> 15390 | G28: =IFERROR('Data Sheet'!F29,0) -> 13726 | H28: =IFERROR('Data Sheet'!G29,0) -> 1722 | I28: =IFERROR('Data Sheet'!H29,0) -> 15970 | J28: =IFERROR('Data Sheet'!I29,0) -> 20376 | ... L28: =IFERROR('Data Sheet'!K29,0) -> 25230 | M28: =IFERROR(SUM('Data Sheet'!H28:K28),0) -> 388636
B29: Effectiv tax Rate | C29: =C28/C25 -> 0.33462771 | D29: =D28/D25 -> 0.33107231 | E29: =E28/E25 -> 0.33738656 | F29: =F28/F25 -> 0.32869866 | G29: =G28/G25 -> 0.3047784 | H29: =H28/H25 -> 0.052136002 | I29: =I28/I25 -> 0.24869579 | J29: =J28/J25 -> 0.24714958 | ... M29: =M28/M25 -> 0.17846119
B31: Net Profit | C31: =C25-C28 -> 17649 | D31: =D25-D28 -> 20611 | E31: =E25-E28 -> 26211 | F31: =F25-F28 -> 31431 | G31: =G25-G28 -> 31310 | H31: =H25-H28 -> 31307 | I31: =I25-I28 -> 48245 | J31: =J25-J28 -> 62068 | ... M31: =M25-M28 -> 1789070
B32: Net Margin | C32: =C31/C4 -> 0.064747251 | D32: =D31/D4 -> 0.067809603 | E32: =E31/E4 -> 0.067066166 | F32: =F31/F4 -> 0.055303456 | G32: =G31/G4 -> 0.052473776 | H32: =H31/H4 -> 0.067138173 | I32: =I31/I4 -> 0.069449943 | J32: =J31/J4 -> 0.070821866 | ... M32: =M31/M4 -> 0.52114957
B34: No.of Equity Shares | C34: =IFERROR('Data Sheet'!B93,0) -> 1382.58 | D34: =IFERROR('Data Sheet'!C93,0) -> 1387.22 | E34: =IFERROR('Data Sheet'!D93,0) -> 1351.39 | F34: =IFERROR('Data Sheet'!E93,0) -> 1352.26 | G34: =IFERROR('Data Sheet'!F93,0) -> 1352.37 | H34: =IFERROR('Data Sheet'!G93,0) -> 1267.89 | I34: =IFERROR('Data Sheet'!H93,0) -> 1352.98 | J34: =IFERROR('Data Sheet'!I93,0) -> 1353.12 | ... M34: =IFERROR('Data Sheet'!L93,0) -> 0
B36: EPS | C36: =IFERROR(C31/C34,0) -> 12.765265 | D36: =IFERROR(D31/D34,0) -> 14.857773 | E36: =IFERROR(E31/E34,0) -> 19.395585 | F36: =IFERROR(F31/F34,0) -> 23.243311 | G36: =IFERROR(G31/G34,0) -> 23.151948 | H36: =IFERROR(H31/H34,0) -> 24.692205 | I36: =IFERROR(I31/I34,0) -> 35.658325 | J36: =IFERROR(J31/J34,0) -> 45.870285 | ... M36: =IFERROR(M31/M34,0) -> 0
B37: EPS Growth % | D37: =D36/C36-1 -> 0.16392203 | E37: =E36/D36-1 -> 0.30541671 | F37: =F36/E36-1 -> 0.19838153 | G37: =G36/F36-1 -> -0.0039307281 | H37: =H36/G36-1 -> 0.066528186 | I37: =I36/H36-1 -> 0.4441126 | J37: =J36/I36-1 -> 0.28638363 | K37: =K36/J36-1 -> 0.012439118 | ... M37: =M36/L36-1 -> -1
B39: Dividend Per Shares | C39: =IFERROR('Data Sheet'!B31/'HISTORICAL FS'!C34,0) -> 2.2388578 | D39: =IFERROR('Data Sheet'!C31/'HISTORICAL FS'!D34,0) -> 2.3463474 | E39: =IFERROR('Data Sheet'!D31/'HISTORICAL FS'!E34,0) -> 2.6292928 | F39: =IFERROR('Data Sheet'!E31/'HISTORICAL FS'!F34,0) -> 2.8484907 | G39: =IFERROR('Data Sheet'!F31/'HISTORICAL FS'!G34,0) -> 3.0467624 | H39: =IFERROR('Data Sheet'!G31/'HISTORICAL FS'!H34,0) -> 3.558274 | I39: =IFERROR('Data Sheet'!H31/'HISTORICAL FS'!I34,0) -> 4.0000591 | J39: =IFERROR('Data Sheet'!I31/'HISTORICAL FS'!J34,0) -> 4.5002661 | ... M39: =IFERROR('Data Sheet'!L31/'HISTORICAL FS'!M34,0) -> 0
B41: Dividend Pay Out Ratio | C41: =IFERROR(C39/C36,0) -> 0.17538671 | D41: =IFERROR(D39/D36,0) -> 0.15792053 | E41: =IFERROR(E39/E36,0) -> 0.13556141 | F41: =IFERROR(F39/F36,0) -> 0.12255098 | G41: =IFERROR(G39/G36,0) -> 0.13159853 | H41: =IFERROR(H39/H36,0) -> 0.14410515 | I41: =IFERROR(I39/I36,0) -> 0.11217743 | J41: =IFERROR(J39/J36,0) -> 0.098108526 | ... M41: =IFERROR(M39/M36,0) -> 0
B43: Retained Earnings | C43: =IFERROR(1-C41,0) -> 0.82461329 | D43: =IFERROR(1-D41,0) -> 0.84207947 | E43: =IFERROR(1-E41,0) -> 0.86443859 | F43: =IFERROR(1-F41,0) -> 0.87744902 | G43: =IFERROR(1-G41,0) -> 0.86840147 | H43: =IFERROR(1-H41,0) -> 0.85589485 | I43: =IFERROR(1-I41,0) -> 0.88782257 | J43: =IFERROR(1-J41,0) -> 0.90189147 | ... M43: =IFERROR(1-M41,0) -> 1
A46: # | B46: Balance Sheet
B47: ='Balance Sheet'!A4 -> Equity Share Capital | C47: =IFERROR( 'Balance Sheet'!B4,0) -> 2948 | D47: =IFERROR( 'Balance Sheet'!C4,0) -> 2959 | E47: =IFERROR( 'Balance Sheet'!D4,0) -> 5922 | F47: =IFERROR( 'Balance Sheet'!E4,0) -> 5926 | G47: =IFERROR( 'Balance Sheet'!F4,0) -> 6339 | H47: =IFERROR( 'Balance Sheet'!G4,0) -> 6445 | I47: =IFERROR( 'Balance Sheet'!H4,0) -> 6765 | J47: =IFERROR( 'Balance Sheet'!I4,0) -> 6766 | ... M47: =IFERROR( 'Balance Sheet'!L4,0) -> 0
B48: ='Balance Sheet'!A5 -> Reserves | C48: =IFERROR( 'Balance Sheet'!B5,0) -> 228608 | D48: =IFERROR( 'Balance Sheet'!C5,0) -> 260750 | E48: =IFERROR( 'Balance Sheet'!D5,0) -> 287584 | F48: =IFERROR( 'Balance Sheet'!E5,0) -> 381186 | G48: =IFERROR( 'Balance Sheet'!F5,0) -> 442827 | H48: =IFERROR( 'Balance Sheet'!G5,0) -> 693727 | I48: =IFERROR( 'Balance Sheet'!H5,0) -> 772720 | J48: =IFERROR( 'Balance Sheet'!I5,0) -> 709106 | ... M48: =IFERROR( 'Balance Sheet'!L5,0) -> 0
B49: ='Balance Sheet'!A6 -> Borrowings | C49: =IFERROR( 'Balance Sheet'!B6,0) -> 194714 | D49: =IFERROR( 'Balance Sheet'!C6,0) -> 217475 | E49: =IFERROR( 'Balance Sheet'!D6,0) -> 239843 | F49: =IFERROR( 'Balance Sheet'!E6,0) -> 307714 | G49: =IFERROR( 'Balance Sheet'!F6,0) -> 355133 | H49: =IFERROR( 'Balance Sheet'!G6,0) -> 278962 | I49: =IFERROR( 'Balance Sheet'!H6,0) -> 319158 | J49: =IFERROR( 'Balance Sheet'!I6,0) -> 451664 | ... M49: =IFERROR( 'Balance Sheet'!L6,0) -> 0
B50: ='Balance Sheet'!A7 -> Other Liabilities | C50: =IFERROR( 'Balance Sheet'!B7,0) -> 172727 | D50: =IFERROR( 'Balance Sheet'!C7,0) -> 225618 | E50: =IFERROR( 'Balance Sheet'!D7,0) -> 277924 | F50: =IFERROR( 'Balance Sheet'!E7,0) -> 302804 | G50: =IFERROR( 'Balance Sheet'!F7,0) -> 358716 | H50: =IFERROR( 'Balance Sheet'!G7,0) -> 340931 | I50: =IFERROR( 'Balance Sheet'!H7,0) -> 399979 | J50: =IFERROR( 'Balance Sheet'!I7,0) -> 438346 | ... M50: =IFERROR( 'Balance Sheet'!L7,0) -> 0
B51: Total Liabilities | C51: =IFERROR( 'Balance Sheet'!B8,0) -> 598997 | D51: =IFERROR( 'Balance Sheet'!C8,0) -> 706802 | E51: =IFERROR( 'Balance Sheet'!D8,0) -> 811273 | F51: =IFERROR( 'Balance Sheet'!E8,0) -> 997630 | G51: =IFERROR( 'Balance Sheet'!F8,0) -> 1163015 | H51: =IFERROR( 'Balance Sheet'!G8,0) -> 1320065 | I51: =IFERROR( 'Balance Sheet'!H8,0) -> 1498622 | J51: =IFERROR( 'Balance Sheet'!I8,0) -> 1605882 | ... M51: =IFERROR( 'Balance Sheet'!L8,0) -> 0
B53: Fixed Asset Net Block | C53: =IFERROR('Balance Sheet'!B10,0) -> 184910 | D53: =IFERROR('Balance Sheet'!C10,0) -> 198526 | E53: =IFERROR('Balance Sheet'!D10,0) -> 403885 | F53: =IFERROR('Balance Sheet'!E10,0) -> 398374 | G53: =IFERROR('Balance Sheet'!F10,0) -> 532658 | H53: =IFERROR('Balance Sheet'!G10,0) -> 541258 | I53: =IFERROR('Balance Sheet'!H10,0) -> 627798 | J53: =IFERROR('Balance Sheet'!I10,0) -> 724805 | ... M53: =IFERROR('Balance Sheet'!L10,0) -> 0
B54: ='Balance Sheet'!A11 -> Capital Work in Progress | C54: =IFERROR('Balance Sheet'!B11,0) -> 228697 | D54: =IFERROR('Balance Sheet'!C11,0) -> 324837 | E54: =IFERROR('Balance Sheet'!D11,0) -> 187022 | F54: =IFERROR('Balance Sheet'!E11,0) -> 179463 | G54: =IFERROR('Balance Sheet'!F11,0) -> 109106 | H54: =IFERROR('Balance Sheet'!G11,0) -> 125953 | I54: =IFERROR('Balance Sheet'!H11,0) -> 172506 | J54: =IFERROR('Balance Sheet'!I11,0) -> 293752 | ... M54: =IFERROR('Balance Sheet'!L11,0) -> 0
B55: ='Balance Sheet'!A12 -> Investments | C55: =IFERROR('Balance Sheet'!B12,0) -> 84015 | D55: =IFERROR('Balance Sheet'!C12,0) -> 82899 | E55: =IFERROR('Balance Sheet'!D12,0) -> 82862 | F55: =IFERROR('Balance Sheet'!E12,0) -> 235635 | G55: =IFERROR('Balance Sheet'!F12,0) -> 276767 | H55: =IFERROR('Balance Sheet'!G12,0) -> 364828 | I55: =IFERROR('Balance Sheet'!H12,0) -> 394264 | J55: =IFERROR('Balance Sheet'!I12,0) -> 235560 | ... M55: =IFERROR('Balance Sheet'!L12,0) -> 0
B56: ='Balance Sheet'!A13 -> Other Assets | C56: =IFERROR('Balance Sheet'!B13-SUM('Data Sheet'!B67:B69),0) -> 39396 | D56: =IFERROR('Balance Sheet'!C13-SUM('Data Sheet'!C67:C69),0) -> 40389 | E56: =IFERROR('Balance Sheet'!D13-SUM('Data Sheet'!D67:D69),0) -> 54857 | F56: =IFERROR('Balance Sheet'!E13-SUM('Data Sheet'!E67:E69),0) -> 75427 | G56: =IFERROR('Balance Sheet'!F13-SUM('Data Sheet'!F67:F69),0) -> 120005 | H56: =IFERROR('Balance Sheet'!G13-SUM('Data Sheet'!G67:G69),0) -> 169943 | I56: =IFERROR('Balance Sheet'!H13-SUM('Data Sheet'!H67:H69),0) -> 136458 | J56: =IFERROR('Balance Sheet'!I13-SUM('Data Sheet'!I67:I69),0) -> 114645 | ... L56: =IFERROR('Balance Sheet'!K13-SUM('Data Sheet'!K67:K69),0) -> 150896 | M56: =IFERROR('Balance Sheet'!L13,0) -> 0
B57: Total Non Current Assets | C57: =SUM(C53:C56) -> 537018 | D57: =SUM(D53:D56) -> 646651 | E57: =SUM(E53:E56) -> 728626 | F57: =SUM(F53:F56) -> 888899 | G57: =SUM(G53:G56) -> 1038536 | H57: =SUM(H53:H56) -> 1201982 | I57: =SUM(I53:I56) -> 1331026 | J57: =SUM(J53:J56) -> 1368762 | ... L57: =SUM(L53:L56) -> 1655028 | M57: =IFERROR('Balance Sheet'!L14,0) -> 0
...

Sheet Data Sheet
A1: COMPANY NAME | B1: RELIANCE INDUSTRIES LTD | E1: =IF(B2<>B3, "A NEW VERSION OF THE WORKSHEET IS AVAILABLE", "")
A2: LATEST VERSION | B2: 2.1 | E2: PLEASE DO NOT MAKE ANY CHANGES TO THIS SHEET
A3: CURRENT VERSION | B3: 2.1
A5: META
A6: Number of shares | B6: =IF(B9>0, B9/B8, 0) -> 1353.1557
A7: Face Value | B7: 10
A8: Current Price | B8: 1452.8
A9: Market Capitalization | B9: 1965864.5
A15: PROFIT & LOSS
A16: Report Date | B16: 42460 | C16: 42825 | D16: 43190 | E16: 43555 | F16: 43921 | G16: 44286 | H16: 44651 | I16: 45016 | J16: 45382 | K16: 45747
A17: Sales | B17: 272583 | C17: 303954 | D17: 390823 | E17: 568337 | F17: 596679 | G17: 466307 | H17: 694673 | I17: 876396 | J17: 899041 | K17: 962820
A18: Raw Material Cost | B18: 186254 | C18: 217518 | D18: 276076 | E18: 399167 | F18: 410288 | G18: 301765 | H18: 494449 | I18: 618746 | J18: 590226 | K18: 644813
A19: Change in Inventory | B19: -2560 | C19: 5218 | D19: 8610 | E19: 4680 | F19: 5048 | G19: 9064 | H19: 21457 | I19: 30263 | J19: 4883 | K19: 15124
A20: Power and Fuel | B20: 10741 | C20: 11251 | D20: 14569 | E20: 17029 | F20: 15098 | G20: 13214 | H20: 17902 | I20: 25062 | J20: 22137 | K20: 23823
A21: Other Mfr. Exp | B21: 8272 | C21: 9909 | D21: 9691 | E21: 12198 | F21: 11434 | G21: 7687 | H21: 12174 | I21: 19658 | J21: 18276 | K21: 18358
A22: Employee Cost | B22: 7407 | C22: 8388 | D22: 9523 | E22: 12488 | F22: 14075 | G22: 14817 | H22: 18758 | I22: 24872 | J22: 25679 | K22: 28559
A23: Selling and admin | B23: 18808 | C23: 18520 | D23: 29111 | E23: 50221 | F23: 62622 | G23: 56154 | H23: 63513 | I23: 67369 | J23: 77292 | K23: 88760
A24: Other Expenses | B24: -3240 | C24: -2721 | D24: -3852 | E24: -2336 | F24: -1056 | G24: 944 | H24: 753 | I24: 8634 | J24: 7816 | K24: 8033
A25: Other Income | B25: 12212 | C25: 9222 | D25: 9869 | E25: 8406 | F25: 8570 | G25: 22432 | H25: 19600 | I25: 12020 | J25: 15792 | K25: 17824
A26: Depreciation | B26: 11565 | C26: 11646 | D26: 16706 | E26: 20934 | F26: 22203 | G26: 26572 | H26: 29782 | I26: 40303 | J26: 50832 | K26: 53136
A27: Interest | B27: 3691 | C27: 3849 | D27: 8052 | E27: 16495 | F27: 22027 | G27: 21189 | H27: 14584 | I27: 19571 | J27: 23118 | K27: 24269
... A31: Dividend Amount | B31: 3095.4 | C31: 3254.9 | D31: 3553.2 | E31: 3851.9 | F31: 4120.35 | G31: 4511.5 | H31: 5412 | I31: 6089.4 | J31: 6766 | K31: 7442.6
A40: Quarters
A41: Report Date | B41: 45107 | C41: 45199 | D41: 45291 | E41: 45382 | F41: 45473 | G41: 45565 | H41: 45657 | I41: 45747 | J41: 45838 | K41: 45930
A42: Sales | B42: 207559 | C42: 231886 | D42: 225086 | E42: 236533 | F42: 231784 | G42: 231535 | H42: 239986 | I42: 261388 | J42: 243632 | K42: 254623
A43: Expenses | B43: 169466 | C43: 190918 | D43: 184430 | E43: 194017 | F43: 193019 | G43: 192477 | H43: 196197 | I43: 217556 | J43: 200727 | K43: 208738
A44: Other Income | B44: 3813 | C44: 3841 | D44: 3869 | E44: 4534 | F44: 3983 | G44: 4876 | H44: 4214 | I44: 4905 | J44: 15119 | K44: 4482
A45: Depreciation | B45: 11775 | C45: 12585 | D45: 12903 | E45: 13569 | F45: 13596 | G45: 12880 | H45: 13181 | I45: 13479 | J45: 13842 | K45: 14416
A46: Interest | B46: 5837 | C46: 5731 | D46: 5789 | E46: 5761 | F46: 5918 | G46: 6017 | H46: 6179 | I46: 6155 | J46: 7036 | K46: 6827
A47: Profit before tax | B47: 24294 | C47: 26493 | D47: 25833 | E47: 27720 | F47: 23234 | G47: 25037 | H47: 28643 | I47: 29103 | J47: 37146 | K47: 29124
A48: Tax | B48: 6112 | C48: 6673 | D48: 6345 | E48: 6577 | F48: 5786 | G48: 5936 | H48: 6839 | I48: 6669 | J48: 6465 | K48: 6978
A49: Net profit | B49: 16011 | C49: 17394 | D49: 17265 | E49: 18951 | F49: 15138 | G49: 16563 | H49: 18540 | I49: 19407 | J49: 26994 | K49: 18165
A50: Operating Profit | B50: 38093 | C50: 40968 | D50: 40656 | E50: 42516 | F50: 38765 | G50: 39058 | H50: 43789 | I50: 43832 | J50: 42905 | K50: 45885
A55: BALANCE SHEET
A56: Report Date | B56: 42460 | C56: 42825 | D56: 43190 | E56: 43555 | F56: 43921 | G56: 44286 | H56: 44651 | I56: 45016 | J56: 45382 | K56: 45747
A57: Equity Share Capital | B57: 2948 | C57: 2959 | D57: 5922 | E57: 5926 | F57: 6339 | G57: 6445 | H57: 6765 | I57: 6766 | J57: 6766 | K57: 13532
A58: Reserves | B58: 228608 | C58: 260750 | D58: 287584 | E58: 381186 | F58: 442827 | G58: 693727 | H58: 772720 | I58: 709106 | J58: 786715 | K58: 829668
A59: Borrowings | B59: 194714 | C59: 217475 | D59: 239843 | E59: 307714 | F59: 355133 | G59: 278962 | H59: 319158 | I59: 451664 | J59: 350719 | K59: 374313
A60: Other Liabilities | B60: 172727 | C60: 225618 | D60: 277924 | E60: 302804 | F60: 358716 | G60: 340931 | H60: 399979 | I60: 438346 | J60: 610848 | K60: 732200
A61: Total | B61: 598997 | C61: 706802 | D61: 811273 | E61: 997630 | F61: 1163015 | G61: 1320065 | H61: 1498622 | I61: 1605882 | J61: 1755048 | K61: 1949713
...

Sheet Ratio Analysis
B2: ="Ratio Analysis of - "&'[1]Data Sheet'!B1 -> Ratio Analysis of - RELIANCE INDUSTRIES LTD
B3: YEARS | C3: =IFERROR('Data Sheet'!B16,0) -> 42460 | D3: =IFERROR('Data Sheet'!C16,0) -> 42825 | E3: =IFERROR('Data Sheet'!D16,0) -> 43190 | F3: =IFERROR('Data Sheet'!E16,0) -> 43555 | G3: =IFERROR('Data Sheet'!F16,0) -> 43921 | H3: =IFERROR('Data Sheet'!G16,0) -> 44286 | I3: =IFERROR('Data Sheet'!H16,0) -> 44651 | J3: =IFERROR('Data Sheet'!I16,0) -> 45016 | ... L3: =IFERROR('Data Sheet'!K16,0) -> 45747 | M3: Trend | N3: Mean | O3: Median
B4: Sales Growth | C4: =IFERROR('HISTORICAL FS'!C5,0) -> - | D4: =IFERROR('HISTORICAL FS'!D5,0) -> 0.11508788 | E4: =IFERROR('HISTORICAL FS'!E5,0) -> 0.28579654 | F4: =IFERROR('HISTORICAL FS'!F5,0) -> 0.45420561 | G4: =IFERROR('HISTORICAL FS'!G5,0) -> 0.0498683 | H4: =IFERROR('HISTORICAL FS'!H5,0) -> -0.21849604 | I4: =IFERROR('HISTORICAL FS'!I5,0) -> 0.48973316 | J4: =IFERROR('HISTORICAL FS'!J5,0) -> 0.26159502 | ... L4: =IFERROR('HISTORICAL FS'!L5,0) -> 0.070941147 | N4: =AVERAGE(D4:L4) -> 0.17050782 | O4: =MEDIAN(D4:L4) -> 0.11508788
B5: EBIDTA Growth | D5: =IFERROR('HISTORICAL FS'!D16/'HISTORICAL FS'!C16-1,0) -> 0.10832675 | E5: =IFERROR('HISTORICAL FS'!E16/'HISTORICAL FS'!D16-1,0) -> 0.38888289 | F5: =IFERROR('HISTORICAL FS'!F16/'HISTORICAL FS'!E16-1,0) -> 0.3099588 | G5: =IFERROR('HISTORICAL FS'!G16/'HISTORICAL FS'!F16-1,0) -> 0.059537092 | H5: =IFERROR('HISTORICAL FS'!H16/'HISTORICAL FS'!G16-1,0) -> -0.094952165 | I5: =IFERROR('HISTORICAL FS'!I16/'HISTORICAL FS'!H16-1,0) -> 0.34399059 | J5: =IFERROR('HISTORICAL FS'!J16/'HISTORICAL FS'!I16-1,0) -> 0.31070813 | K5: =IFERROR('HISTORICAL FS'!K16/'HISTORICAL FS'!J16-1,0) -> 0.14179513 | L5: =IFERROR('HISTORICAL FS'!L16/'HISTORICAL FS'!K16-1,0) -> 0.019077158 | N5: =AVERAGE(D5:L5) -> 0.17636938 | O5: =MEDIAN(D5:L5) -> 0.14179513
B6: EBT Growth | D6: =IFERROR('HISTORICAL FS'!D25/'HISTORICAL FS'!C25-1,0) -> 0.16162111 | E6: =IFERROR('HISTORICAL FS'!E25/'HISTORICAL FS'!D25-1,0) -> 0.28381799 | F6: =IFERROR('HISTORICAL FS'!F25/'HISTORICAL FS'!E25-1,0) -> 0.18363374 | G6: =IFERROR('HISTORICAL FS'!G25/'HISTORICAL FS'!F25-1,0) -> -0.038123919 | H6: =IFERROR('HISTORICAL FS'!H25/'HISTORICAL FS'!G25-1,0) -> -0.26660894 | I6: =IFERROR('HISTORICAL FS'!I25/'HISTORICAL FS'!H25-1,0) -> 0.94420055 | J6: =IFERROR('HISTORICAL FS'!J25/'HISTORICAL FS'!I25-1,0) -> 0.28387448 | K6: =IFERROR('HISTORICAL FS'!K25/'HISTORICAL FS'!J25-1,0) -> 0.074038135 | L6: =IFERROR('HISTORICAL FS'!L25/'HISTORICAL FS'!K25-1,0) -> -0.004009125 | N6: =AVERAGE(D6:L6) -> 0.18027156 | O6: =MEDIAN(D6:L6) -> 0.16162111
B7: Net profit Growth | D7: =IFERROR('HISTORICAL FS'!D31/'HISTORICAL FS'!C31-1,0) -> 0.16782821 | E7: =IFERROR('HISTORICAL FS'!E31/'HISTORICAL FS'!D31-1,0) -> 0.27169958 | F7: =IFERROR('HISTORICAL FS'!F31/'HISTORICAL FS'!E31-1,0) -> 0.19915303 | G7: =IFERROR('HISTORICAL FS'!G31/'HISTORICAL FS'!F31-1,0) -> -0.0038497025 | H7: =IFERROR('HISTORICAL FS'!H31/'HISTORICAL FS'!G31-1,0) -> -9.5816033e-05 | I7: =IFERROR('HISTORICAL FS'!I31/'HISTORICAL FS'!H31-1,0) -> 0.54102916 | J7: =IFERROR('HISTORICAL FS'!J31/'HISTORICAL FS'!I31-1,0) -> 0.28651674 | K7: =IFERROR('HISTORICAL FS'!K31/'HISTORICAL FS'!J31-1,0) -> 0.012454083 | L7: =IFERROR('HISTORICAL FS'!L31/'HISTORICAL FS'!K31-1,0) -> 0.0019414077 | N7: =AVERAGE(D7:L7) -> 0.16407519 | O7: =MEDIAN(D7:L7) -> 0.16782821
B8: Dividend Growth | D8: =IFERROR('HISTORICAL FS'!D39/'HISTORICAL FS'!C39-1,0) -> 0.048010903 | E8: =IFERROR('HISTORICAL FS'!E39/'HISTORICAL FS'!D39-1,0) -> 0.12058975 | F8: =IFERROR('HISTORICAL FS'!F39/'HISTORICAL FS'!E39-1,0) -> 0.083367616 | G8: =IFERROR('HISTORICAL FS'!G39/'HISTORICAL FS'!F39-1,0) -> 0.069605871 | H8: =IFERROR('HISTORICAL FS'!H39/'HISTORICAL FS'!G39-1,0) -> 0.16788695 | I8: =IFERROR('HISTORICAL FS'!I39/'HISTORICAL FS'!H39-1,0) -> 0.12415715 | J8: =IFERROR('HISTORICAL FS'!J39/'HISTORICAL FS'!I39-1,0) -> 0.12504988 | K8: =IFERROR('HISTORICAL FS'!K39/'HISTORICAL FS'!J39-1,0) -> 0.11109469 | L8: =IFERROR('HISTORICAL FS'!L39/'HISTORICAL FS'!K39-1,0) -> 0.099918714 | N8: =AVERAGE(D8:L8) -> 0.10552017 | O8: =MEDIAN(D8:L8) -> 0.11109469
B10: Gross Margin | C10: ='HISTORICAL FS'!C11 -> 0.21039096 | D10: ='HISTORICAL FS'!D11 -> 0.20432697 | E10: ='HISTORICAL FS'!E11 -> 0.22919327 | F10: ='HISTORICAL FS'!F11 -> 0.2324941 | G10: ='HISTORICAL FS'!G11 -> 0.25278584 | H10: ='HISTORICAL FS'!H11 -> 0.29570219 | I10: ='HISTORICAL FS'!I11 -> 0.24881779 | J10: ='HISTORICAL FS'!J11 -> 0.24911227 | ... L10: ='HISTORICAL FS'!L11 -> 0.27252342 | N10: =IFERROR(AVERAGE(C10:L10),0) -> 0.24707581 | O10: =IFERROR(MEDIAN(C10:L10),0) -> 0.24896503
B11: EBIDTA Margin | C11: ='HISTORICAL FS'!C17 -> 0.15327808 | D11: ='HISTORICAL FS'!D17 -> 0.15234871 | E11: ='HISTORICAL FS'!E17 -> 0.16456299 | F11: ='HISTORICAL FS'!F17 -> 0.14823951 | G11: ='HISTORICAL FS'!G17 -> 0.14960473 | H11: ='HISTORICAL FS'!H17 -> 0.17325496 | I11: ='HISTORICAL FS'!I17 -> 0.1563052 | J11: ='HISTORICAL FS'!J17 -> 0.16239006 | ... L11: ='HISTORICAL FS'!L17 -> 0.17199269 | N11: =IFERROR(AVERAGE(C11:L11),0) -> 0.16127229 | O11: =IFERROR(MEDIAN(C11:L11),0) -> 0.15934763
B12: EBIT Margin | C12: =IFERROR('HISTORICAL FS'!C16-'HISTORICAL FS'!C22,0)/'HISTORICAL FS'!C4 -> 0.11085064 | D12: =IFERROR('HISTORICAL FS'!D16-'HISTORICAL FS'!D22,0)/'HISTORICAL FS'!D4 -> 0.1140337 | E12: =IFERROR('HISTORICAL FS'!E16-'HISTORICAL FS'!E22,0)/'HISTORICAL FS'!E4 -> 0.12181729 | F12: =IFERROR('HISTORICAL FS'!F16-'HISTORICAL FS'!F22,0)/'HISTORICAL FS'!F4 -> 0.11140573 | G12: =IFERROR('HISTORICAL FS'!G16-'HISTORICAL FS'!G22,0)/'HISTORICAL FS'!G4 -> 0.11239377 | H12: =IFERROR('HISTORICAL FS'!H16-'HISTORICAL FS'!H22,0)/'HISTORICAL FS'!H4 -> 0.11627104 | I12: =IFERROR('HISTORICAL FS'!I16-'HISTORICAL FS'!I22,0)/'HISTORICAL FS'!I4 -> 0.11343323 | J12: =IFERROR('HISTORICAL FS'!J16-'HISTORICAL FS'!J22,0)/'HISTORICAL FS'!J4 -> 0.11640286 | ... L12: =IFERROR('HISTORICAL FS'!L16-'HISTORICAL FS'!L22,0)/'HISTORICAL FS'!L4 -> 0.1168048 | N12: =IFERROR(AVERAGE(C12:L12),0) -> 0.11576187 | O12: =IFERROR(MEDIAN(C12:L12),0) -> 0.11515237
B13: EBT Margin | C13: ='HISTORICAL FS'!C26 -> 0.09730981 | D13: ='HISTORICAL FS'!D26 -> 0.1013706 | E13: ='HISTORICAL FS'!E26 -> 0.10121462 | F13: ='HISTORICAL FS'!F26 -> 0.08238246 | G13: ='HISTORICAL FS'!G26 -> 0.075477769 | H13: ='HISTORICAL FS'!H26 -> 0.070831019 | I13: ='HISTORICAL FS'!I26 -> 0.092439176 | J13: ='HISTORICAL FS'!J26 -> 0.09407163 | ... L13: ='HISTORICAL FS'!L26 -> 0.091598637 | N13: =IFERROR(AVERAGE(C13:L13),0) -> 0.090518734 | O13: =IFERROR(MEDIAN(C13:L13),0) -> 0.093255403
B14: Net Profit Margin | C14: ='HISTORICAL FS'!C32 -> 0.064747251 | D14: ='HISTORICAL FS'!D32 -> 0.067809603 | E14: ='HISTORICAL FS'!E32 -> 0.067066166 | F14: ='HISTORICAL FS'!F32 -> 0.055303456 | G14: ='HISTORICAL FS'!G32 -> 0.052473776 | H14: ='HISTORICAL FS'!H32 -> 0.067138173 | I14: ='HISTORICAL FS'!I32 -> 0.069449943 | J14: ='HISTORICAL FS'!J32 -> 0.070821866 | ... L14: ='HISTORICAL FS'!L32 -> 0.065394362 | N14: =IFERROR(AVERAGE(C14:L14),0) -> 0.065010241 | O14: =IFERROR(MEDIAN(C14:L14),0) -> 0.067102169
B16: SalesExpenses%Sales | C16: ='HISTORICAL FS'!C14 -> 0.057112879 | D16: ='HISTORICAL FS'!D14 -> 0.05197826 | E16: ='HISTORICAL FS'!E14 -> 0.06463028 | F16: ='HISTORICAL FS'!F14 -> 0.084254588 | G16: ='HISTORICAL FS'!G14 -> 0.10318111 | H16: ='HISTORICAL FS'!H14 -> 0.12244723 | I16: ='HISTORICAL FS'!I14 -> 0.092512592 | J16: ='HISTORICAL FS'!J14 -> 0.086722212 | ... L16: ='HISTORICAL FS'!L14 -> 0.10053073 | N16: =IFERROR(AVERAGE(C16:L16),0) -> 0.08580352 | O16: =IFERROR(MEDIAN(C16:L16),0) -> 0.089617402
B17: Depreciation%Sales | C17: ='HISTORICAL FS'!C23 -> 0.042427444 | D17: ='HISTORICAL FS'!D23 -> 0.038315008 | E17: ='HISTORICAL FS'!E23 -> 0.042745693 | F17: ='HISTORICAL FS'!F23 -> 0.03683378 | G17: ='HISTORICAL FS'!G23 -> 0.037210963 | H17: ='HISTORICAL FS'!H23 -> 0.056983918 | I17: ='HISTORICAL FS'!I23 -> 0.04287197 | J17: ='HISTORICAL FS'!J23 -> 0.045987202 | ... L17: ='HISTORICAL FS'!L23 -> 0.055187886 | N17: =IFERROR(AVERAGE(C17:L17),0) -> 0.045510411 | O17: =IFERROR(MEDIAN(C17:L17),0) -> 0.042808832
B18: Operatingincome%Sales | C18: =C12 -> 0.11085064 | D18: =D12 -> 0.1140337 | E18: =E12 -> 0.12181729 | F18: =F12 -> 0.11140573 | G18: =G12 -> 0.11239377 | H18: =H12 -> 0.11627104 | I18: =I12 -> 0.11343323 | J18: =J12 -> 0.11640286 | ... L18: =L12 -> 0.1168048 | N18: =IFERROR(AVERAGE(C18:L18),0) -> 0.11576187 | O18: =IFERROR(MEDIAN(C18:L18),0) -> 0.11515237
B20: Return on Capital Employed | C20: =('HISTORICAL FS'!C16-'HISTORICAL FS'!C22)/(SUM('HISTORICAL FS'!C47,'HISTORICAL FS'!C48,'HISTORICAL FS'!C49)) -> 0.070884651 | D20: =('HISTORICAL FS'!D16-'HISTORICAL FS'!D22)/(SUM('HISTORICAL FS'!D47,'HISTORICAL FS'!D48,'HISTORICAL FS'!D49)) -> 0.072032736 | E20: =('HISTORICAL FS'!E16-'HISTORICAL FS'!E22)/(SUM('HISTORICAL FS'!E47,'HISTORICAL FS'!E48,'HISTORICAL FS'!E49)) -> 0.089264253 | F20: =('HISTORICAL FS'!F16-'HISTORICAL FS'!F22)/(SUM('HISTORICAL FS'!F47,'HISTORICAL FS'!F48,'HISTORICAL FS'!F49)) -> 0.091124972 | G20: =('HISTORICAL FS'!G16-'HISTORICAL FS'!G22)/(SUM('HISTORICAL FS'!G47,'HISTORICAL FS'!G48,'HISTORICAL FS'!G49)) -> 0.083380683 | H20: =('HISTORICAL FS'!H16-'HISTORICAL FS'!H22)/(SUM('HISTORICAL FS'!H47,'HISTORICAL FS'!H48,'HISTORICAL FS'!H49)) -> 0.055373422 | I20: =('HISTORICAL FS'!I16-'HISTORICAL FS'!I22)/(SUM('HISTORICAL FS'!I47,'HISTORICAL FS'!I48,'HISTORICAL FS'!I49)) -> 0.071723936 | J20: =('HISTORICAL FS'!J16-'HISTORICAL FS'!J22)/(SUM('HISTORICAL FS'!J47,'HISTORICAL FS'!J48,'HISTORICAL FS'!J49)) -> 0.087376321 | ... L20: =('HISTORICAL FS'!L16-'HISTORICAL FS'!L22)/(SUM('HISTORICAL FS'!L47,'HISTORICAL FS'!L48,'HISTORICAL FS'!L49)) -> 0.092370266 | N20: =IFERROR(AVERAGE(C20:L20),0) -> 0.081112432 | O20: =IFERROR(MEDIAN(C20:L20),0) -> 0.085378502
B21: Retained Earnings % | C21: =IFERROR('HISTORICAL FS'!C43,0) -> 0.82461329 | D21: =IFERROR('HISTORICAL FS'!D43,0) -> 0.84207947 | E21: =IFERROR('HISTORICAL FS'!E43,0) -> 0.86443859 | F21: =IFERROR('HISTORICAL FS'!F43,0) -> 0.87744902 | G21: =IFERROR('HISTORICAL FS'!G43,0) -> 0.86840147 | H21: =IFERROR('HISTORICAL FS'!H43,0) -> 0.85589485 | I21: =IFERROR('HISTORICAL FS'!I43,0) -> 0.88782257 | J21: =IFERROR('HISTORICAL FS'!J43,0) -> 0.90189147 | ... L21: =IFERROR('HISTORICAL FS'!L43,0) -> 0.88179407 | N21: =IFERROR(AVERAGE(C21:L21),0) -> 0.86967162 | O21: =IFERROR(MEDIAN(C21:L21),0) -> 0.87292524
B22: Return on Equity % | C22: =IFERROR('HISTORICAL FS'!C31/SUM('HISTORICAL FS'!C47,'HISTORICAL FS'!C48),0) -> 0.076219144 | D22: =IFERROR('HISTORICAL FS'!D31/SUM('HISTORICAL FS'!D47,'HISTORICAL FS'!D48),0) -> 0.078158121 | E22: =IFERROR('HISTORICAL FS'!E31/SUM('HISTORICAL FS'!E47,'HISTORICAL FS'!E48),0) -> 0.089303115 | F22: =IFERROR('HISTORICAL FS'!F31/SUM('HISTORICAL FS'!F47,'HISTORICAL FS'!F48),0) -> 0.081193556 | G22: =IFERROR('HISTORICAL FS'!G31/SUM('HISTORICAL FS'!G47,'HISTORICAL FS'!G48),0) -> 0.069706968 | H22: =IFERROR('HISTORICAL FS'!H31/SUM('HISTORICAL FS'!H47,'HISTORICAL FS'!H48),0) -> 0.044713299 | I22: =IFERROR('HISTORICAL FS'!I31/SUM('HISTORICAL FS'!I47,'HISTORICAL FS'!I48),0) -> 0.06189343 | J22: =IFERROR('HISTORICAL FS'!J31/SUM('HISTORICAL FS'!J47,'HISTORICAL FS'!J48),0) -> 0.086702651 | ... L22: =IFERROR('HISTORICAL FS'!L31/SUM('HISTORICAL FS'!L47,'HISTORICAL FS'!L48),0) -> 0.07467149 | N22: =IFERROR(AVERAGE(C22:L22),0) -> 0.074175838 | O22: =IFERROR(MEDIAN(C22:L22),0) -> 0.077188632
B23: Self Sustained Growth Rate | C23: =C22*C21 -> 0.062851319 | D23: =D22*D21 -> 0.065815349 | E23: =E22*E21 -> 0.077197059 | F23: =F22*F21 -> 0.071243206 | G23: =G22*G21 -> 0.060533633 | H23: =H22*H21 -> 0.038269882 | I23: =I22*I21 -> 0.054950384 | J23: =J22*J21 -> 0.078196381 | ... L23: =L22*L21 -> 0.065844877 | N23: =IFERROR(AVERAGE(C23:L23),0) -> 0.064557171 | O23: =IFERROR(MEDIAN(C23:L23),0) -> 0.065830113
B24: Interest Coverage Ratio | C24: =('HISTORICAL FS'!C16-'HISTORICAL FS'!C22)/'HISTORICAL FS'!C19 -> 8.1863993 | D24: =('HISTORICAL FS'!D16-'HISTORICAL FS'!D22)/'HISTORICAL FS'!D19 -> 9.0051962 | E24: =('HISTORICAL FS'!E16-'HISTORICAL FS'!E22)/'HISTORICAL FS'!E19 -> 5.9126925 | F24: =('HISTORICAL FS'!F16-'HISTORICAL FS'!F22)/'HISTORICAL FS'!F19 -> 3.8384965 | G24: =('HISTORICAL FS'!G16-'HISTORICAL FS'!G22)/'HISTORICAL FS'!G19 -> 3.0445816 | H24: =('HISTORICAL FS'!H16-'HISTORICAL FS'!H22)/'HISTORICAL FS'!H19 -> 2.5587805 | I24: =('HISTORICAL FS'!I16-'HISTORICAL FS'!I22)/'HISTORICAL FS'!I19 -> 5.403113 | J24: =('HISTORICAL FS'!J16-'HISTORICAL FS'!J22)/'HISTORICAL FS'!J19 -> 5.2125594 | ... L24: =('HISTORICAL FS'!L16-'HISTORICAL FS'!L22)/'HISTORICAL FS'!L19 -> 4.6339775 | N24: =IFERROR(AVERAGE(C24:L24),0) -> 5.2626059 | O24: =IFERROR(MEDIAN(C24:L24),0) -> 5.0214108
B26: Debtor Turnover Ratio | C26: =IFERROR('HISTORICAL FS'!C4/'HISTORICAL FS'!C59,0) -> 61.048824 | D26: =IFERROR('HISTORICAL FS'!D4/'HISTORICAL FS'!D59,0) -> 37.171823 | E26: =IFERROR('HISTORICAL FS'!E4/'HISTORICAL FS'!E59,0) -> 22.262774 | F26: =IFERROR('HISTORICAL FS'!F4/'HISTORICAL FS'!F59,0) -> 18.888531 | G26: =IFERROR('HISTORICAL FS'!G4/'HISTORICAL FS'!G59,0) -> 30.356074 | H26: =IFERROR('HISTORICAL FS'!H4/'HISTORICAL FS'!H59,0) -> 24.524403 | I26: =IFERROR('HISTORICAL FS'!I4/'HISTORICAL FS'!I59,0) -> 29.385491 | J26: =IFERROR('HISTORICAL FS'!J4/'HISTORICAL FS'!J59,0) -> 30.806946 | ... L26: =IFERROR('HISTORICAL FS'!L4/'HISTORICAL FS'!L59,0) -> 22.858432 | N26: =IFERROR(AVERAGE(C26:L26),0) -> 30.572878 | O26: =IFERROR(MEDIAN(C26:L26),0) -> 28.905484
B27: Creditor Turnover Rtaio | C27: =IFERROR('HISTORICAL FS'!C4/'HISTORICAL FS'!C50,0) -> 1.5781146 | D27: =IFERROR('HISTORICAL FS'!D4/'HISTORICAL FS'!D50,0) -> 1.3472063 | E27: =IFERROR('HISTORICAL FS'!E4/'HISTORICAL FS'!E50,0) -> 1.4062226 | F27: =IFERROR('HISTORICAL FS'!F4/'HISTORICAL FS'!F50,0) -> 1.8769138 | G27: =IFERROR('HISTORICAL FS'!G4/'HISTORICAL FS'!G50,0) -> 1.6633744 | H27: =IFERROR('HISTORICAL FS'!H4/'HISTORICAL FS'!H50,0) -> 1.367746 | I27: =IFERROR('HISTORICAL FS'!I4/'HISTORICAL FS'!I50,0) -> 1.7367737 | J27: =IFERROR('HISTORICAL FS'!J4/'HISTORICAL FS'!J50,0) -> 1.9993247 | ... L27: =IFERROR('HISTORICAL FS'!L4/'HISTORICAL FS'!L50,0) -> 1.3149686 | N27: =IFERROR(AVERAGE(C27:L27),0) -> 1.5762436 | O27: =IFERROR(MEDIAN(C27:L27),0) -> 1.5249531
B28: Inventory Turnover | C28: =IFERROR('HISTORICAL FS'!C4/'HISTORICAL FS'!C60,0) -> 5.8637654 | D28: =IFERROR('HISTORICAL FS'!D4/'HISTORICAL FS'!D60,0) -> 6.2093522 | E28: =IFERROR('HISTORICAL FS'!E4/'HISTORICAL FS'!E60,0) -> 6.4241005 | F28: =IFERROR('HISTORICAL FS'!F4/'HISTORICAL FS'!F60,0) -> 8.4122053 | G28: =IFERROR('HISTORICAL FS'!G4/'HISTORICAL FS'!G60,0) -> 8.073813 | H28: =IFERROR('HISTORICAL FS'!H4/'HISTORICAL FS'!H60,0) -> 5.7095088 | I28: =IFERROR('HISTORICAL FS'!I4/'HISTORICAL FS'!I60,0) -> 6.4454063 | J28: =IFERROR('HISTORICAL FS'!J4/'HISTORICAL FS'!J60,0) -> 6.2596137 | ... L28: =IFERROR('HISTORICAL FS'!L4/'HISTORICAL FS'!L60,0) -> 6.5918583 | N28: =IFERROR(AVERAGE(C28:L28),0) -> 6.5874555 | O28: =IFERROR(MEDIAN(C28:L28),0) -> 6.3418571
B29: Fixed Asset Turnover | C29: =IFERROR('HISTORICAL FS'!C4/'HISTORICAL FS'!C53,0) -> 1.4741388 | D29: =IFERROR('HISTORICAL FS'!D4/'HISTORICAL FS'!D53,0) -> 1.5310539 | E29: =IFERROR('HISTORICAL FS'!E4/'HISTORICAL FS'!E53,0) -> 0.96765911 | F29: =IFERROR('HISTORICAL FS'!F4/'HISTORICAL FS'!F53,0) -> 1.4266418 | G29: =IFERROR('HISTORICAL FS'!G4/'HISTORICAL FS'!G53,0) -> 1.1201916 | H29: =IFERROR('HISTORICAL FS'!H4/'HISTORICAL FS'!H53,0) -> 0.86152445 | I29: =IFERROR('HISTORICAL FS'!I4/'HISTORICAL FS'!I53,0) -> 1.1065231 | J29: =IFERROR('HISTORICAL FS'!J4/'HISTORICAL FS'!J53,0) -> 1.2091473 | ... L29: =IFERROR('HISTORICAL FS'!L4/'HISTORICAL FS'!L53,0) -> 0.96340479 | N29: =IFERROR(AVERAGE(C29:L29),0) -> 1.1812924 | O29: =IFERROR(MEDIAN(C29:L29),0) -> 1.1364152
B30: Capital Turnover | C30: =IFERROR('HISTORICAL FS'!C4/SUM('HISTORICAL FS'!C47,'HISTORICAL FS'!C48),0) -> 1.1771796 | D30: =IFERROR('HISTORICAL FS'!D4/SUM('HISTORICAL FS'!D47,'HISTORICAL FS'!D48),0) -> 1.1526114 | E30: =IFERROR('HISTORICAL FS'!E4/SUM('HISTORICAL FS'!E47,'HISTORICAL FS'!E48),0) -> 1.3315673 | F30: =IFERROR('HISTORICAL FS'!F4/SUM('HISTORICAL FS'!F47,'HISTORICAL FS'!F48),0) -> 1.4681462 | G30: =IFERROR('HISTORICAL FS'!G4/SUM('HISTORICAL FS'!G47,'HISTORICAL FS'!G48),0) -> 1.3284153 | H30: =IFERROR('HISTORICAL FS'!H4/SUM('HISTORICAL FS'!H47,'HISTORICAL FS'!H48),0) -> 0.66598921 | I30: =IFERROR('HISTORICAL FS'!I4/SUM('HISTORICAL FS'!I47,'HISTORICAL FS'!I48),0) -> 0.89119483 | J30: =IFERROR('HISTORICAL FS'!J4/SUM('HISTORICAL FS'!J47,'HISTORICAL FS'!J48),0) -> 1.2242356 | ... L30: =IFERROR('HISTORICAL FS'!L4/SUM('HISTORICAL FS'!L47,'HISTORICAL FS'!L48),0) -> 1.1418643 | N30: =IFERROR(AVERAGE(C30:L30),0) -> 1.1514238 | O30: =IFERROR(MEDIAN(C30:L30),0) -> 1.1648955
B32: Debtor Days | C32: =IFERROR(365/C26,0) -> 5.9788211 | D32: =IFERROR(365/D26,0) -> 9.8192654 | E32: =IFERROR(365/E26,0) -> 16.395082 | F32: =IFERROR(365/F26,0) -> 19.323896 | G32: =IFERROR(365/G26,0) -> 12.023953 | H32: =IFERROR(365/H26,0) -> 14.883135 | I32: =IFERROR(365/I26,0) -> 12.421096 | J32: =IFERROR(365/J26,0) -> 11.847977 | ... L32: =IFERROR(365/L26,0) -> 15.96785 | N32: =IFERROR(AVERAGE(C32:L32),0) -> 13.150167 | O32: =IFERROR(MEDIAN(C32:L32),0) -> 12.630845
B33: Payable Days | C33: =IFERROR(365/C27,0) -> 231.28865 | D33: =IFERROR(365/D27,0) -> 270.93103 | E33: =IFERROR(365/E27,0) -> 259.56062 | F33: =IFERROR(365/F27,0) -> 194.46818 | G33: =IFERROR(365/G27,0) -> 219.43346 | H33: =IFERROR(365/H27,0) -> 266.86242 | I33: =IFERROR(365/I27,0) -> 210.15979 | J33: =IFERROR(365/J27,0) -> 182.56164 | ... L33: =IFERROR(365/L27,0) -> 277.57317 | N33: =IFERROR(AVERAGE(C33:L33),0) -> 236.0836 | O33: =IFERROR(MEDIAN(C33:L33),0) -> 239.64285
B34: Inventory Days | C34: =IFERROR(365/C28,0) -> 62.246692 | D34: =IFERROR(365/D28,0) -> 58.782299 | E34: =IFERROR(365/E28,0) -> 56.817293 | F34: =IFERROR(365/F28,0) -> 43.389336 | G34: =IFERROR(365/G28,0) -> 45.207884 | H34: =IFERROR(365/H28,0) -> 63.928442 | I34: =IFERROR(365/I28,0) -> 56.629479 | J34: =IFERROR(365/J28,0) -> 58.310307 | ... L34: =IFERROR(365/L28,0) -> 55.371336 | N34: =IFERROR(AVERAGE(C34:L34),0) -> 56.270588 | O34: =IFERROR(MEDIAN(C34:L34),0) -> 57.5638
B35: Cash Conversion Cycle | C35: =C32+C34-C33 -> -163.06314 | D35: =D32+D34-D33 -> -202.32946 | E35: =E32+E34-E33 -> -186.34824 | F35: =F32+F34-F33 -> -131.75494 | G35: =G32+G34-G33 -> -162.20163 | H35: =H32+H34-H33 -> -188.05084 | I35: =I32+I34-I33 -> -141.10922 | J35: =J32+J34-J33 -> -112.40335 | ... L35: =L32+L34-L33 -> -206.23398 | N35: =IFERROR(AVERAGE(C35:L35),0) -> -166.66285 | O35: =IFERROR(MEDIAN(C35:L35),0) -> -168.0984
B37: CFO/Sales | C37: =IFERROR('HISTORICAL FS'!C77/'HISTORICAL FS'!C4,0) -> 0.1686202 | D37: =IFERROR('HISTORICAL FS'!D77/'HISTORICAL FS'!D4,0) -> 0.21389092 | E37: =IFERROR('HISTORICAL FS'!E77/'HISTORICAL FS'!E4,0) -> 0.2302756 | F37: =IFERROR('HISTORICAL FS'!F77/'HISTORICAL FS'!F4,0) -> 0.023866122 | G37: =IFERROR('HISTORICAL FS'!G77/'HISTORICAL FS'!G4,0) -> 0.18903464 | H37: =IFERROR('HISTORICAL FS'!H77/'HISTORICAL FS'!H4,0) -> -0.049323729 | I37: =IFERROR('HISTORICAL FS'!I77/'HISTORICAL FS'!I4,0) -> 0.16033299 | J37: =IFERROR('HISTORICAL FS'!J77/'HISTORICAL FS'!J4,0) -> 0.10885262 | ... L37: =IFERROR('HISTORICAL FS'!L77/'HISTORICAL FS'!L4,0) -> 0.21024387 | N37: =IFERROR(AVERAGE(C37:L37),0) -> 0.14394934 | O37: =IFERROR(MEDIAN(C37:L37),0) -> 0.17616019
B38: CFO/Total Assets | C38: =IFERROR('HISTORICAL FS'!C77/'HISTORICAL FS'!C64,0) -> 0.076733272 | D38: =IFERROR('HISTORICAL FS'!D77/'HISTORICAL FS'!D64,0) -> 0.091981913 | E38: =IFERROR('HISTORICAL FS'!E77/'HISTORICAL FS'!E64,0) -> 0.11093306 | F38: =IFERROR('HISTORICAL FS'!F77/'HISTORICAL FS'!F64,0) -> 0.013596223 | G38: =IFERROR('HISTORICAL FS'!G77/'HISTORICAL FS'!G64,0) -> 0.096983272 | H38: =IFERROR('HISTORICAL FS'!H77/'HISTORICAL FS'!H64,0) -> -0.017423384 | I38: =IFERROR('HISTORICAL FS'!I77/'HISTORICAL FS'!I64,0) -> 0.074320943 | J38: =IFERROR('HISTORICAL FS'!J77/'HISTORICAL FS'!J64,0) -> 0.059405361 | ... L38: =IFERROR('HISTORICAL FS'!L77/'HISTORICAL FS'!L64,0) -> 0.103824 | N38: =IFERROR(AVERAGE(C38:L38),0) -> 0.070445693 | O38: =IFERROR(MEDIAN(C38:L38),0) -> 0.084357593
B39: CFO/Total Debt | C39: =IFERROR('HISTORICAL FS'!C77/'HISTORICAL FS'!C49,0) -> 0.2360539 | D39: =IFERROR('HISTORICAL FS'!D77/'HISTORICAL FS'!D49,0) -> 0.29894471 | E39: =IFERROR('HISTORICAL FS'!E77/'HISTORICAL FS'!E49,0) -> 0.37523296 | F39: =IFERROR('HISTORICAL FS'!F77/'HISTORICAL FS'!F49,0) -> 0.044079892 | G39: =IFERROR('HISTORICAL FS'!G77/'HISTORICAL FS'!G49,0) -> 0.31760777 | H39: =IFERROR('HISTORICAL FS'!H77/'HISTORICAL FS'!H49,0) -> -0.082448506 | I39: =IFERROR('HISTORICAL FS'!I77/'HISTORICAL FS'!I49,0) -> 0.34897762 | J39: =IFERROR('HISTORICAL FS'!J77/'HISTORICAL FS'!J49,0) -> 0.21121453 | ... L39: =IFERROR('HISTORICAL FS'!L77/'HISTORICAL FS'!L49,0) -> 0.54079607 | N39: =IFERROR(AVERAGE(C39:L39),0) -> 0.27613602 | O39: =IFERROR(MEDIAN(C39:L39),0) -> 0.30827624
B41: RETURN ON ASSETS
B42: PAT vs Total Assets | C42: =IFERROR('HISTORICAL FS'!C31/'HISTORICAL FS'!C64,0) -> 0.029464254 | D42: =IFERROR('HISTORICAL FS'!D31/'HISTORICAL FS'!D64,0) -> 0.029160925 | E42: =IFERROR('HISTORICAL FS'!E31/'HISTORICAL FS'!E64,0) -> 0.032308483 | F42: =IFERROR('HISTORICAL FS'!F31/'HISTORICAL FS'!F64,0) -> 0.031505668 | G42: =IFERROR('HISTORICAL FS'!G31/'HISTORICAL FS'!G64,0) -> 0.026921407 | H42: =IFERROR('HISTORICAL FS'!H31/'HISTORICAL FS'!H64,0) -> 0.023716256 | I42: =IFERROR('HISTORICAL FS'!I31/'HISTORICAL FS'!I64,0) -> 0.032192908 | J42: =IFERROR('HISTORICAL FS'!J31/'HISTORICAL FS'!J64,0) -> 0.038650411 | ... L42: =IFERROR('HISTORICAL FS'!L31/'HISTORICAL FS'!L64,0) -> 0.032293471 | N42: =IFERROR(AVERAGE(C42:L42),0) -> 0.031201964 | O42: =IFERROR(MEDIAN(C42:L42),0) -> 0.031849288
B43: EBIT vs Total Assets | C43: =IFERROR(('HISTORICAL FS'!C16-'HISTORICAL FS'!C22)/'HISTORICAL FS'!C64,0) -> 0.050444326 | D43: =IFERROR(('HISTORICAL FS'!D16-'HISTORICAL FS'!D22)/'HISTORICAL FS'!D64,0) -> 0.049039193 | E43: =IFERROR(('HISTORICAL FS'!E16-'HISTORICAL FS'!E22)/'HISTORICAL FS'!E64,0) -> 0.058684315 | F43: =IFERROR(('HISTORICAL FS'!F16-'HISTORICAL FS'!F22)/'HISTORICAL FS'!F64,0) -> 0.063466415 | G43: =IFERROR(('HISTORICAL FS'!G16-'HISTORICAL FS'!G22)/'HISTORICAL FS'!G64,0) -> 0.057663057 | H43: =IFERROR(('HISTORICAL FS'!H16-'HISTORICAL FS'!H22)/'HISTORICAL FS'!H64,0) -> 0.04107222 | I43: =IFERROR(('HISTORICAL FS'!I16-'HISTORICAL FS'!I22)/'HISTORICAL FS'!I64,0) -> 0.052580971 | J43: =IFERROR(('HISTORICAL FS'!J16-'HISTORICAL FS'!J22)/'HISTORICAL FS'!J64,0) -> 0.063525838 | ... L43: =IFERROR(('HISTORICAL FS'!L16-'HISTORICAL FS'!L22)/'HISTORICAL FS'!L64,0) -> 0.05768131 | N43: =IFERROR(AVERAGE(C43:L43),0) -> 0.055778326 | O43: =IFERROR(MEDIAN(C43:L43),0) -> 0.057672183
B44: PAT after Tax benefit vs Total Assets | C44: =(('HISTORICAL FS'!C16-'HISTORICAL FS'!C22)-('HISTORICAL FS'!C19-('HISTORICAL FS'!C19*'HISTORICAL FS'!C29)))/'HISTORICAL FS'!C64 -> 0.046344324 | D44: =(('HISTORICAL FS'!D16-'HISTORICAL FS'!D22)-('HISTORICAL FS'!D19-('HISTORICAL FS'!D19*'HISTORICAL FS'!D29)))/'HISTORICAL FS'!D64 -> 0.045396444 | E44: =(('HISTORICAL FS'!E16-'HISTORICAL FS'!E22)-('HISTORICAL FS'!E19-('HISTORICAL FS'!E19*'HISTORICAL FS'!E29)))/'HISTORICAL FS'!E64 -> 0.052107782 | F44: =(('HISTORICAL FS'!F16-'HISTORICAL FS'!F22)-('HISTORICAL FS'!F19-('HISTORICAL FS'!F19*'HISTORICAL FS'!F29)))/'HISTORICAL FS'!F64 -> 0.052366994 | G44: =(('HISTORICAL FS'!G16-'HISTORICAL FS'!G22)-('HISTORICAL FS'!G19-('HISTORICAL FS'!G19*'HISTORICAL FS'!G29)))/'HISTORICAL FS'!G64 -> 0.044495861 | H44: =(('HISTORICAL FS'!H16-'HISTORICAL FS'!H22)-('HISTORICAL FS'!H19-('HISTORICAL FS'!H19*'HISTORICAL FS'!H29)))/'HISTORICAL FS'!H64 -> 0.025857598 | I44: =(('HISTORICAL FS'!I16-'HISTORICAL FS'!I22)-('HISTORICAL FS'!I19-('HISTORICAL FS'!I19*'HISTORICAL FS'!I29)))/'HISTORICAL FS'!I64 -> 0.045269574 | J44: =(('HISTORICAL FS'!J16-'HISTORICAL FS'!J22)-('HISTORICAL FS'!J19-('HISTORICAL FS'!J19*'HISTORICAL FS'!J29)))/'HISTORICAL FS'!J64 -> 0.054350796 | ... L44: =(('HISTORICAL FS'!L16-'HISTORICAL FS'!L22)-('HISTORICAL FS'!L19-('HISTORICAL FS'!L19*'HISTORICAL FS'!L29)))/'HISTORICAL FS'!L64 -> 0.048794774 | N44: =IFERROR(AVERAGE(C44:L44),0) -> 0.046926161 | O44: =IFERROR(MEDIAN(C44:L44),0) -> 0.047569549
B46: RETURN ON EQUITY
B47: EPS | C47: =IFERROR('HISTORICAL FS'!C36,0) -> 12.765265 | D47: =IFERROR('HISTORICAL FS'!D36,0) -> 14.857773 | E47: =IFERROR('HISTORICAL FS'!E36,0) -> 19.395585 | F47: =IFERROR('HISTORICAL FS'!F36,0) -> 23.243311 | G47: =IFERROR('HISTORICAL FS'!G36,0) -> 23.151948 | H47: =IFERROR('HISTORICAL FS'!H36,0) -> 24.692205 | I47: =IFERROR('HISTORICAL FS'!I36,0) -> 35.658325 | J47: =IFERROR('HISTORICAL FS'!J36,0) -> 45.870285 | ... L47: =IFERROR('HISTORICAL FS'!L36,0) -> 46.527593 | N47: =IFERROR(AVERAGE(C47:L47),0) -> 29.260316 | O47: =IFERROR(MEDIAN(C47:L47),0) -> 23.967758
B48: Cash Flor Earning Per Share | C48: =IFERROR(('HISTORICAL FS'!C31+'HISTORICAL FS'!C22)/'HISTORICAL FS'!C34,0) -> 21.130061 | D48: =IFERROR(('HISTORICAL FS'!D31+'HISTORICAL FS'!D22)/'HISTORICAL FS'!D34,0) -> 23.252981 | E48: =IFERROR(('HISTORICAL FS'!E31+'HISTORICAL FS'!E22)/'HISTORICAL FS'!E34,0) -> 31.757672 | F48: =IFERROR(('HISTORICAL FS'!F31+'HISTORICAL FS'!F22)/'HISTORICAL FS'!F34,0) -> 38.724062 | G48: =IFERROR(('HISTORICAL FS'!G31+'HISTORICAL FS'!G22)/'HISTORICAL FS'!G34,0) -> 39.569792 | H48: =IFERROR(('HISTORICAL FS'!H31+'HISTORICAL FS'!H22)/'HISTORICAL FS'!H34,0) -> 45.649859 | I48: =IFERROR(('HISTORICAL FS'!I31+'HISTORICAL FS'!I22)/'HISTORICAL FS'!I34,0) -> 57.670476 | J48: =IFERROR(('HISTORICAL FS'!J31+'HISTORICAL FS'!J22)/'HISTORICAL FS'!J34,0) -> 75.655522 | ... L48: =IFERROR(('HISTORICAL FS'!L31+'HISTORICAL FS'!L22)/'HISTORICAL FS'!L34,0) -> 85.793355 | N48: =IFERROR(AVERAGE(C48:L48),0) -> 50.321061 | O48: =IFERROR(MEDIAN(C48:L48),0) -> 42.609826
B49: Dividened Per Share | C49: ='HISTORICAL FS'!C39 -> 2.2388578 | D49: ='HISTORICAL FS'!D39 -> 2.3463474 | E49: ='HISTORICAL FS'!E39 -> 2.6292928 | F49: ='HISTORICAL FS'!F39 -> 2.8484907 | G49: ='HISTORICAL FS'!G39 -> 3.0467624 | H49: ='HISTORICAL FS'!H39 -> 3.558274 | I49: ='HISTORICAL FS'!I39 -> 4.0000591 | J49: ='HISTORICAL FS'!J39 -> 4.5002661 | ... L49: ='HISTORICAL FS'!L39 -> 5.4998374 | N49: =IFERROR(AVERAGE(C49:L49),0) -> 3.5668409 | O49: =IFERROR(MEDIAN(C49:L49),0) -> 3.3025182
...

Sheet Forcasting
B2: ='Data Sheet'!B1&"-"&'Data Sheet'!A17 -> RELIANCE INDUSTRIES LTD-Sales | G2: ='Data Sheet'!$B$1&"-"&'HISTORICAL FS'!B16&"Forecasting" -> RELIANCE INDUSTRIES LTD-EBIDAForecasting | L2: ='Data Sheet'!$B$1&"-"&'HISTORICAL FS'!B36&"-"&"Forecasting" -> RELIANCE INDUSTRIES LTD-EPS-Forecasting
B3: Year Weight | C3: Year | D3: Salas | E3: Salas Growth | G3: Year Weight | H3: Year | I3: Salas | J3: Salas Growth | L3: Year Weight | M3: Year | N3: Salas | O3: Salas Growth
B4: 1 | C4: 2016 | D4: {=TRANSPOSE('Data Sheet'!B17:K17)} -> 272583 | E4: - | G4: 1 | H4: 2016 | I4: {=TRANSPOSE('HISTORICAL FS'!C16:L16)} -> 41781 | J4: - | L4: 1 | M4: 2016 | N4: {=TRANSPOSE('HISTORICAL FS'!C36:L36)} -> 12.765265 | O4: -
B5: 2 | C5: 2017 | D5: 303954 | E5: =D5/D4-1 -> 0.11508788 | G5: 2 | H5: 2017 | I5: 46307 | J5: =I5/I4-1 -> 0.10832675 | L5: 2 | M5: 2017 | N5: 14.857773 | O5: =N5/N4-1 -> 0.16392203
B6: 3 | C6: 2018 | D6: 390823 | E6: =D6/D5-1 -> 0.28579654 | G6: 3 | H6: 2018 | I6: 64315 | J6: =I6/I5-1 -> 0.38888289 | L6: 3 | M6: 2018 | N6: 19.395585 | O6: =N6/N5-1 -> 0.30541671
B7: 4 | C7: 2019 | D7: 568337 | E7: =D7/D6-1 -> 0.45420561 | G7: 4 | H7: 2019 | I7: 84250 | J7: =I7/I6-1 -> 0.3099588 | L7: 4 | M7: 2019 | N7: 23.243311 | O7: =N7/N6-1 -> 0.19838153
B8: 5 | C8: 2020 | D8: 596679 | E8: =D8/D7-1 -> 0.0498683 | G8: 5 | H8: 2020 | I8: 89266 | J8: =I8/I7-1 -> 0.059537092 | L8: 5 | M8: 2020 | N8: 23.151948 | O8: =N8/N7-1 -> -0.0039307281
B9: 6 | C9: 2021 | D9: 466307 | E9: =D9/D8-1 -> -0.21849604 | G9: 6 | H9: 2021 | I9: 80790 | J9: =I9/I8-1 -> -0.094952165 | L9: 6 | M9: 2021 | N9: 24.692205 | O9: =N9/N8-1 -> 0.066528186
B10: 7 | C10: 2022 | D10: 694673 | E10: =D10/D9-1 -> 0.48973316 | G10: 7 | H10: 2022 | I10: 108581 | J10: =I10/I9-1 -> 0.34399059 | L10: 7 | M10: 2022 | N10: 35.658325 | O10: =N10/N9-1 -> 0.4441126
B11: 8 | C11: 2023 | D11: 876396 | E11: =D11/D10-1 -> 0.26159502 | G11: 8 | H11: 2023 | I11: 142318 | J11: =I11/I10-1 -> 0.31070813 | L11: 8 | M11: 2023 | N11: 45.870285 | O11: =N11/N10-1 -> 0.28638363
B12: 9 | C12: 2024 | D12: 899041 | E12: =D12/D11-1 -> 0.025838776 | G12: 9 | H12: 2024 | I12: 162498 | J12: =I12/I11-1 -> 0.14179513 | L12: 9 | M12: 2024 | N12: 46.440871 | O12: =N12/N11-1 -> 0.012439118
B13: 10 | C13: 2025 | D13: 962820 | E13: =D13/D12-1 -> 0.070941147 | G13: 10 | H13: 2025 | I13: 165598 | J13: =I13/I12-1 -> 0.019077158 | L13: 10 | M13: 2025 | N13: 46.527593 | O13: =N13/N12-1 -> 0.0018673675
B14: 11 | C14: 2026 | D14: =FORECAST(B14,$D$4:$D$13,$B$4:$B$13) -> 1038302.7 | E14: =D14/D13-1 -> 0.078397554 | G14: 11 | H14: 2026 | I14: =FORECAST(G14,$I$4:$I$13,$G$4:$G$13) -> 177977.8 | J14: =I14/I13-1 -> 0.074758149 | L14: 11 | M14: 2026 | N14: =FORECAST(L14,$N$4:$N$13,$L$4:$L$13) -> 52.463697 | O14: =N14/N13-1 -> 0.12758245
B15: 12 | C15: 2027 | D15: =FORECAST(B15,$D$4:$D$13,$B$4:$B$13) -> 1117419.4 | E15: =D15/D14-1 -> 0.076198031 | G15: 12 | H15: 2027 | I15: =FORECAST(G15,$I$4:$I$13,$G$4:$G$13) -> 192415.51 | J15: =I15/I14-1 -> 0.081120843 | L15: 12 | M15: 2027 | N15: =FORECAST(L15,$N$4:$N$13,$L$4:$L$13) -> 56.682494 | O15: =N15/N14-1 -> 0.080413634
B16: 13 | C16: 2028 | D16: =FORECAST(B16,$D$4:$D$13,$B$4:$B$13) -> 1196536 | E16: =D16/D15-1 -> 0.070802983 | G16: 13 | H16: 2028 | I16: =FORECAST(G16,$I$4:$I$13,$G$4:$G$13) -> 206853.22 | J16: =I16/I15-1 -> 0.07503402 | L16: 13 | M16: 2028 | N16: =FORECAST(L16,$N$4:$N$13,$L$4:$L$13) -> 60.90129 | O16: =N16/N15-1 -> 0.074428563
B17: 14 | C17: 2029 | D17: =FORECAST(B17,$D$4:$D$13,$B$4:$B$13) -> 1275652.6 | E17: =D17/D16-1 -> 0.066121392 | G17: 14 | H17: 2029 | I17: =FORECAST(G17,$I$4:$I$13,$G$4:$G$13) -> 221290.93 | J17: =I17/I16-1 -> 0.069796879 | L17: 14 | M17: 2029 | N17: =FORECAST(L17,$N$4:$N$13,$L$4:$L$13) -> 65.120087 | O17: =N17/N16-1 -> 0.069272696
B18: 15 | C18: 2030 | D18: =FORECAST(B18,$D$4:$D$13,$B$4:$B$13) -> 1354769.2 | E18: =D18/D17-1 -> 0.062020509 | G18: 15 | H18: 2030 | I18: =FORECAST(G18,$I$4:$I$13,$G$4:$G$13) -> 235728.64 | J18: =I18/I17-1 -> 0.065243114 | L18: 15 | M18: 2030 | N18: =FORECAST(L18,$N$4:$N$13,$L$4:$L$13) -> 69.338883 | O18: =N18/N17-1 -> 0.064784873
B19: 16 | C19: 2031 | D19: =FORECAST(B19,$D$4:$D$13,$B$4:$B$13) -> 1433885.9 | E19: =D19/D18-1 -> 0.058398598 | G19: 16 | H19: 2031 | I19: =FORECAST(G19,$I$4:$I$13,$G$4:$G$13) -> 250166.35 | J19: =I19/I18-1 -> 0.061247158 | L19: 16 | M19: 2031 | N19: =FORECAST(L19,$N$4:$N$13,$L$4:$L$13) -> 73.55768 | O19: =N19/N18-1 -> 0.060843157

Sheet CFS
C3: 41699 | D3: 42064 | E3: 42430 | F3: 42795 | G3: 43160 | H3: 43525 | I3: 43891 | J3: 44256 | K3: 44621 | L3: 44986 | M3: 45352 | N3: 45717
B4: Cash from Operating Activity - | C4: 43261 | D4: 34374 | E4: 38134 | F4: 49550 | G4: 71459 | H4: 42346 | I4: 94877 | J4: 26958 | K4: 110654 | L4: 115032 | M4: 158788 | N4: 178703
B5: Profit from operations | C5: 38444 | D5: 38994 | E5: 38887 | F5: 44170 | G5: 62765 | H5: 83319 | I5: 85347 | J5: 80129 | K5: 113726 | L5: 140963 | M5: 164383 | N5: 166904
B6: Receivables | C6: -1913 | D6: 1097 | E6: -6880 | F6: -8511 | G6: -21991 | H6: -40136 | I6: -13792 | J6: 959 | K6: -14180 | L6: 13194 | M6: -15674 | N6: -17837
B7: Inventory | C7: -1396 | D7: 3472 | E7: 6758 | F7: -6899 | G7: -10474 | H7: -6724 | I7: -6342 | J7: -7769 | K7: -24983 | L7: -32228 | M7: -12756 | N7: 3134
B8: Payables | C8: 14339 | D8: -2754 | E8: 7951 | F8: 30873 | G8: 51003 | H8: 18078 | I8: 38050 | J8: -43148 | K8: 39888 | L8: -600 | M8: 34796 | N8: 38427
B9: Working capital changes | C9: 11030 | D9: 1815 | E9: 7829 | F9: 15463 | G9: 18538 | H9: -28782 | I9: 17916 | J9: -49958 | K9: 725 | L9: -19634 | M9: 6366 | N9: 23724
B10: Direct taxes | C10: -6213 | D10: -6435 | E10: -8582 | F10: -10083 | G10: -9844 | H10: -12191 | I10: -8386 | J10: -3213 | K10: -3797 | L10: -6297 | M10: -11961 | N10: -11925
B11: Cash from Investing Activity - | C11: -73070 | D11: -64706 | E11: -36186 | F11: -66201 | G11: -68192 | H11: -94507 | I11: -72497 | J11: -142385 | K11: -109162 | L11: -93001 | M11: -113581 | N11: -137535
B12: Fixed assets purchased | C12: -60087 | D12: -63364 | E12: -46898 | F12: -78109 | G12: -73953 | H12: -93626 | I12: -76517 | J12: -105837 | K12: -100145 | L12: -140988 | M12: -152883 | N12: -139967
B13: Fixed assets sold | C13: 148 | D13: 402 | E13: 344 | F13: 1482 | G13: 999 | H13: 849 | I13: 964 | J13: 2319 | K13: 3137 | L13: 9186 | M13: 15307 | N13: 2343
B14: Investments purchased | C14: -765659 | D14: -678241 | E14: -715334 | F14: -654760 | G14: -533984 | H14: -1107439 | I14: -1156843 | J14: -689866 | K14: -667878 | L14: -471822 | M14: -513660 | N14: -684340
B15: Investments sold | C15: 749849 | D15: 666383 | E15: 721182 | F15: 663990 | G15: 537504 | H15: 1103615 | I15: 1174796 | J15: 642551 | K15: 668137 | L15: 501266 | M15: 531355 | N15: 672558
... B28: Net Cash Flow | C28: -16096 | D28: -21888 | E28: -1262 | F28: -8034 | G28: 1266 | H28: 3745 | I28: 19839 | J28: -13523 | K28: 18781 | L28: 32486 | M28: 28561 | N28: 9277

Sheet wacc
B2: Weighted Average Cost of Capital
B4: All figures are in INR unless otherwise stated
B6: Peer Company
G7: Debt/ | H7: Debt/ | I7: Levered | J7: Unlevered | K7: Unlevered
B8: Name of the Comp | D8: Country | E8: Total Debt | F8: Total Equity | G8: Tax Rate 1 | H8: Equity | I8: Capital | J8: Beta 2 | K8: Beta 3
B9: Avenue Super. | D9: India | E9: ='[2]BETA Comps.'!F3 -> 630.38 | F9: ='[2]BETA Comps.'!E3 -> 279783.37 | G9: 0.3 | H9: =E9/F9 -> 0.0022531003 | I9: =E9/(E9+F9) -> 0.0022480353 | J9: =[2]Sheet2!L6 -> 1.2681188 | K9: =J9/(1+(1-G9)*H9) -> 1.2661219
B10: Trent | D10: India | E10: ='[2]BETA Comps.'!F4 -> 4839.33 | F10: ='[2]BETA Comps.'!E4 -> 140524.04 | G10: 0.3 | H10: =E10/F10 -> 0.034437737 | I10: =E10/(E10+F10) -> 0.033291262 | J10: 1 | K10: =J10/(1+(1-G10)*H10) -> 0.97646102
B11: Vedant Fashions | D11: India | E11: ='[2]BETA Comps.'!F5 -> 365.02 | F11: ='[2]BETA Comps.'!E5 -> 22671.01 | G11: 0.3 | H11: =E11/F11 -> 0.016100738 | I11: =E11/(E11+F11) -> 0.015845612 | J11: 1 | K11: =J11/(1+(1-G11)*H11) -> 0.98885509
B12: Aditya Bir. Fas. | D12: India | E12: ='[2]BETA Comps.'!F6 -> 10174.77 | F12: ='[2]BETA Comps.'!E6 -> 19500.64 | G12: 0.3 | H12: =E12/F12 -> 0.52176595 | I12: =E12/(E12+F12) -> 0.34286873 | J12: 1 | K12: =J12/(1+(1-G12)*H12) -> 0.732474
B13: Redtape | D13: India | E13: ='[2]BETA Comps.'!F7 -> 470.82 | F13: ='[2]BETA Comps.'!E7 -> 8657.28 | G13: 0.3 | H13: =E13/F13 -> 0.054384287 | I13: =E13/(E13+F13) -> 0.05157919 | J13: 1 | K13: =J13/(1+(1-G13)*H13) -> 0.9633271
E16: Averages | F16: =AVERAGE(G9:G13) -> 0.3 | G16: =AVERAGE(H9:H13) -> 0.12578836 | H16: =AVERAGE(I9:I13) -> 0.089166565 | I16: 1 | J16: =I16/(1+(1-F16)*G16) -> 0.91907384
E17: Medaian | F17: =MEDIAN(G9:G13) -> 0.3 | G17: =MEDIAN(H9:H13) -> 0.034437737 | H17: =MEDIAN(I9:I13) -> 0.033291262 | I17: 1 | J17: =I17/(1+(1-F17)*G17) -> 0.97646102
B20: Cost of Debt | G20: Cost of Equity
B22: Pre-Tax Cost of debt | E22: 0.084 | G22: Risk Free Rate | K22: 0.065
B23: Tax Rat | E23: 0.3 | G23: Equity Risk Premium | K23: 0.08
B24: Poat Tax Cost Debt | E24: =E22*(1-E23) -> 0.0588 | G24: Levered Beta 4 | K24: =K33 -> 1.4816735
G25: Cost of Equity | K25: =K22+K23*K24 -> 0.18353388
B28: Capital Structure | G28: Levered Beta
D30: Current | E30: Target | G30: Comes Median Unliverd Beta | K30: =J17 -> 0.97646102
B31: Total Debt | C31: 17440 | D31: =C31/$C$33 -> 0.35087013 | E31: 0.425 | G31: Target Debt/Equity | K31: =E35 -> 0.73913043
B32: Market Capitalization | C32: 32265 | D32: =C32/$C$33 -> 0.64912987 | E32: =E33-E31 -> 0.575 | G32: Tax | K32: =E23 -> 0.3
B33: Total Capital | C33: =C31+C32 -> 49705 | D33: =C33/$C$33 -> 1 | E33: 1 | G33: Levered Beta | K33: =K30*(1+(1-K32)*K31) -> 1.4816735
B35: Debt/Equity | D35: =D31/D32 -> 0.54052379 | E35: =E31/E32 -> 0.73913043 | G35: Weighted Average Cost of Capital
J37: Total Cost | K37: Total Weight
G38: Debt | J38: =E24 -> 0.0588 | K38: =E31 -> 0.425
B39: Notes:- | G39: Equity | J39: =K25 -> 0.18353388 | K39: =E32 -> 0.575
B40: 1. Tax Rate considered as Marginal Tax Rate for the Country | G40: Weight Average Cost of Capital | K40: =SUMPRODUCT(J38:J39,K38:K39) -> 0.13052198
B41: 2. Levered Beta is based on 5 years monthly data
B42: 3.Unlevered Beta = Levered Beta/(1+(1-Tax Rate)*Debt/Equity)
B43: 4.Levered Beta = Unlevered Beta*(1+(1-Tax Rate)*Debt/Equity)

Sheet DCF
B3: Calculation of PV of FCFF | G3: Mar-25A | H3: 46082 | I3: 46448 | J3: 46815 | K3: 47181 | L3: 47547
B5: EBIT | G5: ='Intrisic Growth '!L34 -> 112462 | H5: =G5*(1+$G$21) -> 126254.85 | I5: =H5*(1+H21) -> 126254.85 | J5: =I5*(1+I21) -> 126254.85 | K5: =J5*(1+J21) -> 126254.85 | L5: =K5*(1+K21) -> 126254.85
B7: Tax Rate | G7: ='Intrisic Growth '!L45 -> 0.28607713 | H7: 0.2861 | I7: 0.2861 | J7: 0.2861 | K7: 0.2861 | L7: 0.2861
B9: EBIT(1-T) | G9: =G5*(1-G7) -> 80289.194 | H9: =G9*(1+$G$21) -> 90136.226 | I9: =H9*(1+$G$21) -> 101190.94 | J9: =I9*(1+$G$21) -> 113601.46 | K9: =J9*(1+$G$21) -> 127534.06 | L9: =K9*(1+$G$21) -> 143175.41
B11: Less:- Reinvestment Rate | G11: ='Intrisic Growth '!P50 -> 0.85810062 | H11: =G11*(1+$G$21) -> 0.96334198 | I11: =H11*(1+$G$21) -> 1.0814906 | J11: =I11*(1+$G$21) -> 1.2141295 | K11: =J11*(1+$G$21) -> 1.3630359 | L11: =K11*(1+$G$21) -> 1.5302048
B13: Free Cash Flow to Firm (FCFF) | G13: =G9*(1-G11) -> 11392.987 | H13: =G13*(1+$G$21) -> 12790.274 | I13: =H13*(1+$G$21) -> 14358.932 | J13: =I13*(1+$G$21) -> 16119.976 | K13: =J13*(1+$G$21) -> 18097.003 | L13: =K13*(1+$G$21) -> 20316.502
B15: Mid Year Convention | H15: 0.5 | I15: =H15+1 -> 1.5 | J15: =I15+1 -> 2.5 | K15: =J15+1 -> 3.5 | L15: =K15+1 -> 4.5
B17: Discounting Factor | H17: =1/(1+$G$23)^H15 -> 0.94050367 | I17: =1/(1+$G$23)^I15 -> 0.83191985 | J17: =1/(1+$G$23)^J15 -> 0.73587233 | K17: =1/(1+$G$23)^K15 -> 0.65091378 | L17: =1/(1+$G$23)^L15 -> 0.57576393
B19: PV of FCFF | H19: =H13*H17 -> 12029.3 | I19: =I13*I17 -> 11945.48 | J19: =J13*J17 -> 11862.244 | K19: =K13*K17 -> 11779.589 | L19: =L13*L17 -> 11697.509
B21: Expected Growth | G21: ='Intrisic Growth '!P56 -> 0.12264454
B22: Terminal Growth | G22: 0.059
B23: WACC | G23: =wacc!K40 -> 0.13052198
B26: Calculation of Terminal Value
B27: FCFF(n+1) | E27: =L13*(1+$G$21) -> 22808.21
B28: WACC | E28: =G23 -> 0.13052198
B29: Terminal Growth Rate | E29: 0.0509
B31: Terminal Value | E31: =E27/(E28-E29) -> 286456.2
B34: Calculation of Equity Value Per Share
B35: PV of FCFF | E35: =SUM(H19:L19) -> 59314.122
B36: PV of Terminal Value | E36: =E31*L17 -> 164931.15
B37: Value of Operating Assets | E37: =SUM(E35,E36) -> 224245.27
B39: Add: CASH | E39: ='Data Sheet'!K69 -> 106502
B40: Less:- DEBT | E40: ='RAW FS'!N7 -> 236899
B42: Value of Equity | E42: =E37+E39-E40 -> 93848.271
B43: NO. of Shares | E43: ='Data Sheet'!B6 -> 1353.1557
B44: Euity Value Per Share | E44: =E42/E43 -> 69.355119
B46: Share Price | E46: 1465
B47: Discount/Premium | E47: =E46/E44 -> 21.123171

Sheet RAW FS
B2: Particular | C2: 41699 | D2: 42064 | E2: 42430 | F2: 42795 | G2: 43160 | H2: 43525 | I2: 43891 | J2: 44256 | K2: 44621 | L2: 44986 | M2: 45352 | N2: 45717
